Workbook

Sheet Foglio5
A1: Etichette di riga | B1: Somma di Etica Azionario
A2: 42012 | B2: 189.52662
A3: Trim1 | B3: 189.52662
A4: 42013 | B4: 188.53047
A5: Trim1 | B5: 188.53047
A6: 42016 | B6: 189.1061
A7: Trim1 | B7: 189.1061
A8: 42017 | B8: 190.17086
A9: Trim1 | B9: 190.17086
A10: 42018 | B10: 188.87728
A11: Trim1 | B11: 188.87728
A12: 42019 | B12: 191.90988
A13: Trim1 | B13: 191.90988
A14: 42020 | B14: 193.81093
A15: Trim1 | B15: 193.81093
A16: 42023 | B16: 192.97891
A17: Trim1 | B17: 192.97891
A18: 42024 | B18: 194.30751
A19: Trim1 | B19: 194.30751
A20: 42025 | B20: 194.96898
A21: Trim1 | B21: 194.96898
A22: 42026 | B22: 199.04331
A23: Trim1 | B23: 199.04331
A24: 42027 | B24: 201.80093
A25: Trim1 | B25: 201.80093
A26: 42030 | B26: 202.12655
A27: Trim1 | B27: 202.12655
A28: 42031 | B28: 199.89381
A29: Trim1 | B29: 199.89381
A30: 42032 | B30: 199.87946
A31: Trim1 | B31: 199.87946
A32: 42033 | B32: 199.61572
A33: Trim1 | B33: 199.61572
A34: 42034 | B34: 199.25594
A35: Trim1 | B35: 199.25594
A36: 42037 | B36: 199.34155
A37: Trim1 | B37: 199.34155
A38: 42038 | B38: 199.9392
A39: Trim1 | B39: 199.9392
A40: 42039 | B40: 201.11922
...

Sheet Quote Lorde
B1: A81 | C1: A82 | D1: A83 | E1: A88 | F1: A80 | G1: A98 | H1: A99
A2: Data | B2: Etica Obbligazionario Breve Termine | C2: Etica Obbligazionario Misto | D2: Etica Bilanciato | E2: Etica Azionario | F2: Etica Rendita Bilanciata | G2: Etica Transizione Climatica | H2: Etica Obiettivo Sociale
A3: 42012 | B3: 137.79362 | C3: 182.87896 | D3: 266.07553 | E3: 189.52662
A4: 42013 | B4: 137.77664 | C4: 182.69043 | D4: 265.09259 | E4: 188.53047
A5: 42016 | B5: 137.8287 | C5: 183.03754 | D5: 265.85887 | E5: 189.1061
A6: 42017 | B6: 137.82385 | C6: 183.18979 | D6: 266.90447 | E6: 190.17086
A7: 42018 | B7: 137.86974 | C7: 183.53613 | D7: 266.08333 | E7: 188.87728
A8: 42019 | B8: 137.90503 | C8: 183.99903 | D8: 269.01465 | E8: 191.90988
A9: 42020 | B9: 138.01438 | C9: 184.70121 | D9: 271.13484 | E9: 193.81093
A10: 42023 | B10: 138.07687 | C10: 184.60604 | D10: 270.45892 | E10: 192.97891
A11: 42024 | B11: 138.09816 | C11: 184.76053 | D11: 271.7241 | E11: 194.30751
A12: 42025 | B12: 138.10874 | C12: 184.57553 | D12: 272.12365 | E12: 194.96898
A13: 42026 | B13: 138.28191 | C13: 185.96776 | D13: 276.64738 | E13: 199.04331
A14: 42027 | B14: 138.27838 | C14: 186.76804 | D14: 279.57861 | E14: 201.80093
... A184: 42271 | B184: 138.90835 | C184: 184.36288 | D184: 271.24553 | E184: 195.77752
A185: 42272 | B185: 138.88883 | C185: 184.50823 | D185: 274.35314 | E185: 199.15232 | F185: 100
A186: 42275 | B186: 138.93801 | C186: 184.44047 | D186: 271.14271 | E186: 195.55077 | F186: 99.908537
A187: 42276 | B187: 138.93311 | C187: 184.33509 | D187: 269.89771 | E187: 194.21208 | F187: 99.593395
A188: 42277 | B188: 138.95445 | C188: 184.90063 | D188: 273.93647 | E188: 198.3216 | F188: 100.23385
A189: 42278 | B189: 139.01367 | C189: 185.347 | D189: 274.28603 | E189: 198.2733 | F189: 100.37245
A190: 42279 | B190: 139.06377 | C190: 185.73027 | D190: 275.09024 | E190: 198.88575 | F190: 100.56064
A191: 42282 | B191: 139.08028 | C191: 186.05028 | D191: 279.10792 | E191: 203.15469 | F191: 101.08658
A192: 42283 | B192: 139.06127 | C192: 185.76479 | D192: 278.74387 | E192: 202.93178 | F192: 100.93582
A193: 42284 | B193: 139.08808 | C193: 186.00277 | D193: 279.82953 | E193: 203.99008 | F193: 101.15031
A194: 42285 | B194: 139.06997 | C194: 186.2111 | D194: 280.86575 | E194: 204.9565 | F194: 101.33485
A195: 42286 | B195: 139.08062 | C195: 186.2299 | D195: 281.84613 | E195: 206.02601 | F195: 101.4675
A196: 42289 | B196: 139.09135 | C196: 186.40015 | D196: 281.77383 | E196: 205.8032 | F196: 101.48165
... A948: 43384 | B948: 140.10246 | C948: 197.13022 | D948: 330.13928 | E948: 250.18434 | F948: 111.37993
A949: 43385 | B949: 140.0943 | C949: 197.29056 | D949: 331.20459 | E949: 251.34 | F949: 111.55555 | G949: 100
A950: 43388 | B950: 140.12838 | C950: 197.2248 | D950: 330.56658 | E950: 250.62434 | F950: 111.44484 | G950: 99.622357
A951: 43389 | B951: 140.18736 | C951: 198.01937 | D951: 334.7202 | E951: 254.99638 | F951: 112.18234 | G951: 100.69226
A952: 43390 | B952: 140.15972 | C952: 198.10416 | D952: 335.13471 | E952: 255.41308 | F952: 112.27057 | G952: 100.86956
A953: 43391 | B953: 140.08127 | C953: 197.89211 | D953: 334.35145 | E953: 254.57972 | F953: 112.12287 | G953: 100.89169
A954: 43392 | B954: 140.22874 | C954: 197.79475 | D954: 333.20327 | E954: 253.34557 | F954: 111.94609 | G954: 100.71524
A955: 43395 | B955: 140.23384 | C955: 197.91939 | D955: 333.07976 | E955: 253.092 | F955: 111.96606 | G955: 100.71397
A956: 43396 | B956: 140.18513 | C956: 197.69023 | D956: 330.82387 | E956: 250.53974 | F956: 111.61188 | G956: 100.42844
A957: 43397 | B957: 140.17138 | C957: 197.5723 | D957: 329.48372 | E957: 249.05566 | F957: 111.4403 | G957: 100.09945
A958: 43398 | B958: 140.18716 | C958: 197.66213 | D958: 329.41937 | E958: 248.84636 | F958: 111.43063 | G958: 99.884051
A959: 43399 | B959: 140.22221 | C959: 197.78624 | D959: 328.38355 | E959: 247.48335 | F959: 111.32296 | G959: 99.43848
A960: 43402 | B960: 140.30095 | C960: 198.00445 | D960: 328.93231 | E960: 248.00802 | F960: 111.44024 | G960: 99.598433
...

Sheet Performance Lorde
A1: Data | B1: Etica Obbligazionario Breve Termine | C1: Etica Obbligazionario Misto | D1: Etica Bilanciato | E1: Etica Azionario | F1: Etica Rendita Bilanciata | G1: Etica Transizione Climatica | H1: Etica Obiettivo Sociale
A2: 42013 | B2: ='Quote Lorde'!B4/'Quote Lorde'!B3-1 -> -0.00012322018 | C2: ='Quote Lorde'!C4/'Quote Lorde'!C3-1 -> -0.0010308945 | D2: ='Quote Lorde'!D4/'Quote Lorde'!D3-1 -> -0.0036942017 | E2: =IFERROR(('Quote Lorde'!E4/'Quote Lorde'!E3-1),"") -> -0.0052560039 | F2: =IFERROR(('Quote Lorde'!F4/'Quote Lorde'!F3-1),"") | G2: =IFERROR(('Quote Lorde'!G4/'Quote Lorde'!G3-1),"") | H2: =IFERROR(('Quote Lorde'!H4/'Quote Lorde'!H3-1),"")
A3: 42016 | B3: ='Quote Lorde'!B5/'Quote Lorde'!B4-1 -> 0.00037780488 | C3: ='Quote Lorde'!C5/'Quote Lorde'!C4-1 -> 0.0018999647 | D3: ='Quote Lorde'!D5/'Quote Lorde'!D4-1 -> 0.002890593 | E3: =IFERROR(('Quote Lorde'!E5/'Quote Lorde'!E4-1),"") -> 0.0030532674 | F3: =IFERROR(('Quote Lorde'!F5/'Quote Lorde'!F4-1),"") | G3: =IFERROR(('Quote Lorde'!G5/'Quote Lorde'!G4-1),"") | H3: =IFERROR(('Quote Lorde'!H5/'Quote Lorde'!H4-1),"")
A4: 42017 | B4: ='Quote Lorde'!B6/'Quote Lorde'!B5-1 -> -3.5134555e-05 | C4: ='Quote Lorde'!C6/'Quote Lorde'!C5-1 -> 0.00083182026 | D4: ='Quote Lorde'!D6/'Quote Lorde'!D5-1 -> 0.0039329314 | E4: =IFERROR(('Quote Lorde'!E6/'Quote Lorde'!E5-1),"") -> 0.0056304701 | F4: =IFERROR(('Quote Lorde'!F6/'Quote Lorde'!F5-1),"") | G4: =IFERROR(('Quote Lorde'!G6/'Quote Lorde'!G5-1),"") | H4: =IFERROR(('Quote Lorde'!H6/'Quote Lorde'!H5-1),"")
A5: 42018 | B5: ='Quote Lorde'!B7/'Quote Lorde'!B6-1 -> 0.00033291576 | C5: ='Quote Lorde'!C7/'Quote Lorde'!C6-1 -> 0.0018905816 | D5: ='Quote Lorde'!D7/'Quote Lorde'!D6-1 -> -0.0030765371 | E5: =IFERROR(('Quote Lorde'!E7/'Quote Lorde'!E6-1),"") -> -0.0068022021 | F5: =IFERROR(('Quote Lorde'!F7/'Quote Lorde'!F6-1),"") | G5: =IFERROR(('Quote Lorde'!G7/'Quote Lorde'!G6-1),"") | H5: =IFERROR(('Quote Lorde'!H7/'Quote Lorde'!H6-1),"")
A6: 42019 | B6: ='Quote Lorde'!B8/'Quote Lorde'!B7-1 -> 0.00025595707 | C6: ='Quote Lorde'!C8/'Quote Lorde'!C7-1 -> 0.0025221272 | D6: ='Quote Lorde'!D8/'Quote Lorde'!D7-1 -> 0.011016535 | E6: =IFERROR(('Quote Lorde'!E8/'Quote Lorde'!E7-1),"") -> 0.016055946 | F6: =IFERROR(('Quote Lorde'!F8/'Quote Lorde'!F7-1),"") | G6: =IFERROR(('Quote Lorde'!G8/'Quote Lorde'!G7-1),"") | H6: =IFERROR(('Quote Lorde'!H8/'Quote Lorde'!H7-1),"")
A7: 42020 | B7: ='Quote Lorde'!B9/'Quote Lorde'!B8-1 -> 0.00079296235 | C7: ='Quote Lorde'!C9/'Quote Lorde'!C8-1 -> 0.0038162095 | D7: ='Quote Lorde'!D9/'Quote Lorde'!D8-1 -> 0.0078813392 | E7: =IFERROR(('Quote Lorde'!E9/'Quote Lorde'!E8-1),"") -> 0.0099059245 | F7: =IFERROR(('Quote Lorde'!F9/'Quote Lorde'!F8-1),"") | G7: =IFERROR(('Quote Lorde'!G9/'Quote Lorde'!G8-1),"") | H7: =IFERROR(('Quote Lorde'!H9/'Quote Lorde'!H8-1),"")
A8: 42023 | B8: ='Quote Lorde'!B10/'Quote Lorde'!B9-1 -> 0.00045280915 | C8: ='Quote Lorde'!C10/'Quote Lorde'!C9-1 -> -0.00051524108 | D8: ='Quote Lorde'!D10/'Quote Lorde'!D9-1 -> -0.0024929231 | E8: =IFERROR(('Quote Lorde'!E10/'Quote Lorde'!E9-1),"") -> -0.0042929026 | F8: =IFERROR(('Quote Lorde'!F10/'Quote Lorde'!F9-1),"") | G8: =IFERROR(('Quote Lorde'!G10/'Quote Lorde'!G9-1),"") | H8: =IFERROR(('Quote Lorde'!H10/'Quote Lorde'!H9-1),"")
A9: 42024 | B9: ='Quote Lorde'!B11/'Quote Lorde'!B10-1 -> 0.00015414779 | C9: ='Quote Lorde'!C11/'Quote Lorde'!C10-1 -> 0.00083686884 | D9: ='Quote Lorde'!D11/'Quote Lorde'!D10-1 -> 0.0046778757 | E9: =IFERROR(('Quote Lorde'!E11/'Quote Lorde'!E10-1),"") -> 0.0068846603 | F9: =IFERROR(('Quote Lorde'!F11/'Quote Lorde'!F10-1),"") | G9: =IFERROR(('Quote Lorde'!G11/'Quote Lorde'!G10-1),"") | H9: =IFERROR(('Quote Lorde'!H11/'Quote Lorde'!H10-1),"")
A10: 42025 | B10: ='Quote Lorde'!B12/'Quote Lorde'!B11-1 -> 7.663822e-05 | C10: ='Quote Lorde'!C12/'Quote Lorde'!C11-1 -> -0.0010013044 | D10: ='Quote Lorde'!D12/'Quote Lorde'!D11-1 -> 0.0014704435 | E10: =IFERROR(('Quote Lorde'!E12/'Quote Lorde'!E11-1),"") -> 0.0034042262 | F10: =IFERROR(('Quote Lorde'!F12/'Quote Lorde'!F11-1),"") | G10: =IFERROR(('Quote Lorde'!G12/'Quote Lorde'!G11-1),"") | H10: =IFERROR(('Quote Lorde'!H12/'Quote Lorde'!H11-1),"")
A11: 42026 | B11: ='Quote Lorde'!B13/'Quote Lorde'!B12-1 -> 0.0012538671 | C11: ='Quote Lorde'!C13/'Quote Lorde'!C12-1 -> 0.0075428427 | D11: ='Quote Lorde'!D13/'Quote Lorde'!D12-1 -> 0.01662378 | E11: =IFERROR(('Quote Lorde'!E13/'Quote Lorde'!E12-1),"") -> 0.020897325 | F11: =IFERROR(('Quote Lorde'!F13/'Quote Lorde'!F12-1),"") | G11: =IFERROR(('Quote Lorde'!G13/'Quote Lorde'!G12-1),"") | H11: =IFERROR(('Quote Lorde'!H13/'Quote Lorde'!H12-1),"")
A12: 42027 | B12: ='Quote Lorde'!B14/'Quote Lorde'!B13-1 -> -2.5535551e-05 | C12: ='Quote Lorde'!C14/'Quote Lorde'!C13-1 -> 0.0043033387 | D12: ='Quote Lorde'!D14/'Quote Lorde'!D13-1 -> 0.010595574 | E12: =IFERROR(('Quote Lorde'!E14/'Quote Lorde'!E13-1),"") -> 0.013854379 | F12: =IFERROR(('Quote Lorde'!F14/'Quote Lorde'!F13-1),"") | G12: =IFERROR(('Quote Lorde'!G14/'Quote Lorde'!G13-1),"") | H12: =IFERROR(('Quote Lorde'!H14/'Quote Lorde'!H13-1),"")
A13: 42030 | B13: ='Quote Lorde'!B15/'Quote Lorde'!B14-1 -> -0.00037903009 | C13: ='Quote Lorde'!C15/'Quote Lorde'!C14-1 -> -0.00033923058 | D13: ='Quote Lorde'!D15/'Quote Lorde'!D14-1 -> 0.00076439937 | E13: =IFERROR(('Quote Lorde'!E15/'Quote Lorde'!E14-1),"") -> 0.0016135991 | F13: =IFERROR(('Quote Lorde'!F15/'Quote Lorde'!F14-1),"") | G13: =IFERROR(('Quote Lorde'!G15/'Quote Lorde'!G14-1),"") | H13: =IFERROR(('Quote Lorde'!H15/'Quote Lorde'!H14-1),"")
... A2775: 46055 | B2775: ='Quote Lorde'!B2777/'Quote Lorde'!B2776-1 -> -0.00029627953 | C2775: ='Quote Lorde'!C2777/'Quote Lorde'!C2776-1 -> 7.3496749e-05 | D2775: ='Quote Lorde'!D2777/'Quote Lorde'!D2776-1 -> 0.0057601938 | E2775: =IFERROR(('Quote Lorde'!E2777/'Quote Lorde'!E2776-1),"") -> 0.0095523825 | F2775: =IFERROR(('Quote Lorde'!F2777/'Quote Lorde'!F2776-1),"") -> 0.0026780965 | G2775: =IFERROR(('Quote Lorde'!G2777/'Quote Lorde'!G2776-1),"") -> 0.0075939044 | H2775: =IFERROR(('Quote Lorde'!H2777/'Quote Lorde'!H2776-1),"") -> 0.0027265828
A2776: {=[1]!nbd(A2775)} -> #VALUE! | B2776: ='Quote Lorde'!B2778/'Quote Lorde'!B2777-1 -> #VALUE! | C2776: ='Quote Lorde'!C2778/'Quote Lorde'!C2777-1 -> #VALUE! | D2776: ='Quote Lorde'!D2778/'Quote Lorde'!D2777-1 -> #VALUE! | E2776: =IFERROR(('Quote Lorde'!E2778/'Quote Lorde'!E2777-1),"") | F2776: =IFERROR(('Quote Lorde'!F2778/'Quote Lorde'!F2777-1),"") | G2776: =IFERROR(('Quote Lorde'!G2778/'Quote Lorde'!G2777-1),"") | H2776: =IFERROR(('Quote Lorde'!H2778/'Quote Lorde'!H2777-1),"")

Sheet Volatilità
A1: Data | B1: Etica Obbligazionario Breve Termine | C1: Etica Obbligazionario Misto | D1: Etica Bilanciato | E1: Etica Azionario | F1: Etica Rendita Bilanciata | G1: Etica Transizione Climatica | H1: Etica Obiettivo Sociale
A2: 42373 | B2: =STDEV('Performance Lorde'!B2:B261)*SQRT(260) -> 0.0063981493 | C2: =STDEV('Performance Lorde'!C2:C261)*SQRT(260) -> 0.045236346 | D2: =STDEV('Performance Lorde'!D2:D261)*SQRT(260) -> 0.11916867 | E2: =STDEV('Performance Lorde'!E2:E261)*SQRT(260) -> 0.15729445 | F2: =STDEV('Performance Lorde'!F2:F261)*SQRT(260) -> 0.062319593
A3: 42374 | B3: =STDEV('Performance Lorde'!B3:B262)*SQRT(260) -> 0.0064034198 | C3: =STDEV('Performance Lorde'!C3:C262)*SQRT(260) -> 0.04537164 | D3: =STDEV('Performance Lorde'!D3:D262)*SQRT(260) -> 0.11940269 | E3: =STDEV('Performance Lorde'!E3:E262)*SQRT(260) -> 0.15749692 | F3: =STDEV('Performance Lorde'!F3:F262)*SQRT(260) -> 0.062614546
A4: 42376 | B4: =STDEV('Performance Lorde'!B4:B263)*SQRT(260) -> 0.0063972309 | C4: =STDEV('Performance Lorde'!C4:C263)*SQRT(260) -> 0.045423768 | D4: =STDEV('Performance Lorde'!D4:D263)*SQRT(260) -> 0.12035275 | E4: =STDEV('Performance Lorde'!E4:E263)*SQRT(260) -> 0.15889968 | F4: =STDEV('Performance Lorde'!F4:F263)*SQRT(260) -> 0.063499459
A5: 42377 | B5: =STDEV('Performance Lorde'!B5:B264)*SQRT(260) -> 0.0063973953 | C5: =STDEV('Performance Lorde'!C5:C264)*SQRT(260) -> 0.04541833 | D5: =STDEV('Performance Lorde'!D5:D264)*SQRT(260) -> 0.12038357 | E5: =STDEV('Performance Lorde'!E5:E264)*SQRT(260) -> 0.15897175 | F5: =STDEV('Performance Lorde'!F5:F264)*SQRT(260) -> 0.063196989
A6: 42380 | B6: =STDEV('Performance Lorde'!B6:B265)*SQRT(260) -> 0.0063907638 | C6: =STDEV('Performance Lorde'!C6:C265)*SQRT(260) -> 0.045450306 | D6: =STDEV('Performance Lorde'!D6:D265)*SQRT(260) -> 0.12048555 | E6: =STDEV('Performance Lorde'!E6:E265)*SQRT(260) -> 0.15898055 | F6: =STDEV('Performance Lorde'!F6:F265)*SQRT(260) -> 0.06309851
A7: 42381 | B7: =STDEV('Performance Lorde'!B7:B266)*SQRT(260) -> 0.0063875636 | C7: =STDEV('Performance Lorde'!C7:C266)*SQRT(260) -> 0.045384484 | D7: =STDEV('Performance Lorde'!D7:D266)*SQRT(260) -> 0.11999363 | E7: =STDEV('Performance Lorde'!E7:E266)*SQRT(260) -> 0.1581901 | F7: =STDEV('Performance Lorde'!F7:F266)*SQRT(260) -> 0.062712706
A8: 42382 | B8: =STDEV('Performance Lorde'!B8:B267)*SQRT(260) -> 0.006343262 | C8: =STDEV('Performance Lorde'!C8:C267)*SQRT(260) -> 0.045236885 | D8: =STDEV('Performance Lorde'!D8:D267)*SQRT(260) -> 0.11996897 | E8: =STDEV('Performance Lorde'!E8:E267)*SQRT(260) -> 0.15818619 | F8: =STDEV('Performance Lorde'!F8:F267)*SQRT(260) -> 0.062627208
A9: 42383 | B9: =STDEV('Performance Lorde'!B9:B268)*SQRT(260) -> 0.0063385303 | C9: =STDEV('Performance Lorde'!C9:C268)*SQRT(260) -> 0.045908389 | D9: =STDEV('Performance Lorde'!D9:D268)*SQRT(260) -> 0.12204197 | E9: =STDEV('Performance Lorde'!E9:E268)*SQRT(260) -> 0.16032523 | F9: =STDEV('Performance Lorde'!F9:F268)*SQRT(260) -> 0.066064701
A10: 42384 | B10: =STDEV('Performance Lorde'!B10:B269)*SQRT(260) -> 0.0063379474 | C10: =STDEV('Performance Lorde'!C10:C269)*SQRT(260) -> 0.045942685 | D10: =STDEV('Performance Lorde'!D10:D269)*SQRT(260) -> 0.12196571 | E10: =STDEV('Performance Lorde'!E10:E269)*SQRT(260) -> 0.16018778 | F10: =STDEV('Performance Lorde'!F10:F269)*SQRT(260) -> 0.06576709
A11: 42387 | B11: =STDEV('Performance Lorde'!B11:B270)*SQRT(260) -> 0.0063384694 | C11: =STDEV('Performance Lorde'!C11:C270)*SQRT(260) -> 0.045971229 | D11: =STDEV('Performance Lorde'!D11:D270)*SQRT(260) -> 0.1224735 | E11: =STDEV('Performance Lorde'!E11:E270)*SQRT(260) -> 0.16082606 | F11: =STDEV('Performance Lorde'!F11:F270)*SQRT(260) -> 0.065964406
A12: 42388 | B12: =STDEV('Performance Lorde'!B12:B271)*SQRT(260) -> 0.0062206198 | C12: =STDEV('Performance Lorde'!C12:C271)*SQRT(260) -> 0.045357254 | D12: =STDEV('Performance Lorde'!D12:D271)*SQRT(260) -> 0.12165535 | E12: =STDEV('Performance Lorde'!E12:E271)*SQRT(260) -> 0.15988809 | F12: =STDEV('Performance Lorde'!F12:F271)*SQRT(260) -> 0.065915438
A13: 42389 | B13: =STDEV('Performance Lorde'!B13:B272)*SQRT(260) -> 0.0062231742 | C13: =STDEV('Performance Lorde'!C13:C272)*SQRT(260) -> 0.045245479 | D13: =STDEV('Performance Lorde'!D13:D272)*SQRT(260) -> 0.12133491 | E13: =STDEV('Performance Lorde'!E13:E272)*SQRT(260) -> 0.15942905 | F13: =STDEV('Performance Lorde'!F13:F272)*SQRT(260) -> 0.065936707
... A688: 43370 | B688: =STDEV('Performance Lorde'!B688:B947)*SQRT(260) -> 0.010752884 | C688: =STDEV('Performance Lorde'!C688:C947)*SQRT(260) -> 0.022588927 | D688: =STDEV('Performance Lorde'!D688:D947)*SQRT(260) -> 0.06174624 | E688: =STDEV('Performance Lorde'!E688:E947)*SQRT(260) -> 0.084696981 | F688: =STDEV('Performance Lorde'!F688:F947)*SQRT(260) -> 0.034163038
A689: 43371 | B689: =STDEV('Performance Lorde'!B689:B948)*SQRT(260) -> 0.010755775 | C689: =STDEV('Performance Lorde'!C689:C948)*SQRT(260) -> 0.022580241 | D689: =STDEV('Performance Lorde'!D689:D948)*SQRT(260) -> 0.061613824 | E689: =STDEV('Performance Lorde'!E689:E948)*SQRT(260) -> 0.084497035 | F689: =STDEV('Performance Lorde'!F689:F948)*SQRT(260) -> 0.034102591 | I689: {=_xlfn.SEQUENCE(260)} -> 1
A690: 43374 | B690: =STDEV('Performance Lorde'!B690:B949)*SQRT(260) -> 0.010764258 | C690: =STDEV('Performance Lorde'!C690:C949)*SQRT(260) -> 0.022935326 | D690: =STDEV('Performance Lorde'!D690:D949)*SQRT(260) -> 0.062841592 | E690: =STDEV('Performance Lorde'!E690:E949)*SQRT(260) -> 0.086214322 | F690: =STDEV('Performance Lorde'!F690:F949)*SQRT(260) -> 0.034723433 | I690: 2
A691: 43375 | B691: =STDEV('Performance Lorde'!B691:B950)*SQRT(260) -> 0.010765888 | C691: =STDEV('Performance Lorde'!C691:C950)*SQRT(260) -> 0.02293262 | D691: =STDEV('Performance Lorde'!D691:D950)*SQRT(260) -> 0.062842039 | E691: =STDEV('Performance Lorde'!E691:E950)*SQRT(260) -> 0.086216249 | F691: =STDEV('Performance Lorde'!F691:F950)*SQRT(260) -> 0.034723044 | I691: 3
A692: 43376 | B692: =STDEV('Performance Lorde'!B692:B951)*SQRT(260) -> 0.010779698 | C692: =STDEV('Performance Lorde'!C692:C951)*SQRT(260) -> 0.022928902 | D692: =STDEV('Performance Lorde'!D692:D951)*SQRT(260) -> 0.062827421 | E692: =STDEV('Performance Lorde'!E692:E951)*SQRT(260) -> 0.086210241 | F692: =STDEV('Performance Lorde'!F692:F951)*SQRT(260) -> 0.034700861 | I692: 4
A693: 43377 | B693: =STDEV('Performance Lorde'!B693:B952)*SQRT(260) -> 0.010831694 | C693: =STDEV('Performance Lorde'!C693:C952)*SQRT(260) -> 0.022930516 | D693: =STDEV('Performance Lorde'!D693:D952)*SQRT(260) -> 0.06291109 | E693: =STDEV('Performance Lorde'!E693:E952)*SQRT(260) -> 0.086330374 | F693: =STDEV('Performance Lorde'!F693:F952)*SQRT(260) -> 0.034727482 | I693: 5
A694: 43378 | B694: =STDEV('Performance Lorde'!B694:B953)*SQRT(260) -> 0.010830772 | C694: =STDEV('Performance Lorde'!C694:C953)*SQRT(260) -> 0.022931293 | D694: =STDEV('Performance Lorde'!D694:D953)*SQRT(260) -> 0.062912648 | E694: =STDEV('Performance Lorde'!E694:E953)*SQRT(260) -> 0.086335192 | F694: =STDEV('Performance Lorde'!F694:F953)*SQRT(260) -> 0.034727421 | I694: 6
A695: 43381 | B695: =STDEV('Performance Lorde'!B695:B954)*SQRT(260) -> 0.010836067 | C695: =STDEV('Performance Lorde'!C695:C954)*SQRT(260) -> 0.022953642 | D695: =STDEV('Performance Lorde'!D695:D954)*SQRT(260) -> 0.063265768 | E695: =STDEV('Performance Lorde'!E695:E954)*SQRT(260) -> 0.086916079 | F695: =STDEV('Performance Lorde'!F695:F954)*SQRT(260) -> 0.034859498 | I695: 7
A696: 43382 | B696: =STDEV('Performance Lorde'!B696:B955)*SQRT(260) -> 0.010836423 | C696: =STDEV('Performance Lorde'!C696:C955)*SQRT(260) -> 0.022961825 | D696: =STDEV('Performance Lorde'!D696:D955)*SQRT(260) -> 0.063403218 | E696: =STDEV('Performance Lorde'!E696:E955)*SQRT(260) -> 0.087129254 | F696: =STDEV('Performance Lorde'!F696:F955)*SQRT(260) -> 0.03489638 | I696: 8
A697: 43383 | B697: =STDEV('Performance Lorde'!B697:B956)*SQRT(260) -> 0.010837016 | C697: =STDEV('Performance Lorde'!C697:C956)*SQRT(260) -> 0.022953555 | D697: =STDEV('Performance Lorde'!D697:D956)*SQRT(260) -> 0.063400101 | E697: =STDEV('Performance Lorde'!E697:E956)*SQRT(260) -> 0.087132964 | F697: =STDEV('Performance Lorde'!F697:F956)*SQRT(260) -> 0.03489141 | I697: 9
A698: 43384 | B698: =STDEV('Performance Lorde'!B698:B957)*SQRT(260) -> 0.010839505 | C698: =STDEV('Performance Lorde'!C698:C957)*SQRT(260) -> 0.022904483 | D698: =STDEV('Performance Lorde'!D698:D957)*SQRT(260) -> 0.063406278 | E698: =STDEV('Performance Lorde'!E698:E957)*SQRT(260) -> 0.087235435 | F698: =STDEV('Performance Lorde'!F698:F957)*SQRT(260) -> 0.034847762 | I698: 10
A699: 43385 | B699: =STDEV('Performance Lorde'!B699:B958)*SQRT(260) -> 0.01085112 | C699: =STDEV('Performance Lorde'!C699:C958)*SQRT(260) -> 0.022864038 | D699: =STDEV('Performance Lorde'!D699:D958)*SQRT(260) -> 0.063355778 | E699: =STDEV('Performance Lorde'!E699:E958)*SQRT(260) -> 0.087193239 | F699: =STDEV('Performance Lorde'!F699:F958)*SQRT(260) -> 0.034801316 | I699: 11
A700: 43388 | B700: =STDEV('Performance Lorde'!B700:B959)*SQRT(260) -> 0.010868335 | C700: =STDEV('Performance Lorde'!C700:C959)*SQRT(260) -> 0.022858473 | D700: =STDEV('Performance Lorde'!D700:D959)*SQRT(260) -> 0.063603394 | E700: =STDEV('Performance Lorde'!E700:E959)*SQRT(260) -> 0.08763209 | F700: =STDEV('Performance Lorde'!F700:F959)*SQRT(260) -> 0.034863706 | I700: 12
A701: 43389 | B701: =STDEV('Performance Lorde'!B701:B960)*SQRT(260) -> 0.010872912 | C701: =STDEV('Performance Lorde'!C701:C960)*SQRT(260) -> 0.022897092 | D701: =STDEV('Performance Lorde'!D701:D960)*SQRT(260) -> 0.063842767 | E701: =STDEV('Performance Lorde'!E701:E960)*SQRT(260) -> 0.087977515 | F701: =STDEV('Performance Lorde'!F701:F960)*SQRT(260) -> 0.035006983 | I701: 13
... A948: 43749 | B948: =STDEV('Performance Lorde'!B948:B1207)*SQRT(260) -> 0.004362208 | C948: =STDEV('Performance Lorde'!C948:C1207)*SQRT(260) -> 0.019744315 | D948: =STDEV('Performance Lorde'!D948:D1207)*SQRT(260) -> 0.067956255 | E948: =STDEV('Performance Lorde'!E948:E1207)*SQRT(260) -> 0.1020402 | F948: =STDEV('Performance Lorde'!F948:F1207)*SQRT(260) -> 0.035787662 | I948: 260
A949: 43752 | B949: =STDEV('Performance Lorde'!B949:B1208)*SQRT(260) -> 0.0043582923 | C949: =STDEV('Performance Lorde'!C949:C1208)*SQRT(260) -> 0.019740437 | D949: =STDEV('Performance Lorde'!D949:D1208)*SQRT(260) -> 0.067928687 | E949: =STDEV('Performance Lorde'!E949:E1208)*SQRT(260) -> 0.10200044 | F949: =STDEV('Performance Lorde'!F949:F1208)*SQRT(260) -> 0.035770385 | G949: =IFERROR(STDEV('Performance Lorde'!G949:G1208)*SQRT(260),"-") -> 0.055572887
A950: 43753 | B950: =STDEV('Performance Lorde'!B950:B1209)*SQRT(260) -> 0.0043408771 | C950: =STDEV('Performance Lorde'!C950:C1209)*SQRT(260) -> 0.019374269 | D950: =STDEV('Performance Lorde'!D950:D1209)*SQRT(260) -> 0.066836273 | E950: =STDEV('Performance Lorde'!E950:E1209)*SQRT(260) -> 0.10059028 | F950: =STDEV('Performance Lorde'!F950:F1209)*SQRT(260) -> 0.035211777 | G950: =IFERROR(STDEV('Performance Lorde'!G950:G1209)*SQRT(260),"-") -> 0.054584442
A951: 43754 | B951: =STDEV('Performance Lorde'!B951:B1210)*SQRT(260) -> 0.0043372386 | C951: =STDEV('Performance Lorde'!C951:C1210)*SQRT(260) -> 0.019397094 | D951: =STDEV('Performance Lorde'!D951:D1210)*SQRT(260) -> 0.066896844 | E951: =STDEV('Performance Lorde'!E951:E1210)*SQRT(260) -> 0.10070961 | F951: =STDEV('Performance Lorde'!F951:F1210)*SQRT(260) -> 0.035218775 | G951: =IFERROR(STDEV('Performance Lorde'!G951:G1210)*SQRT(260),"-") -> 0.054586035
A952: 43755 | B952: =STDEV('Performance Lorde'!B952:B1211)*SQRT(260) -> 0.0042976613 | C952: =STDEV('Performance Lorde'!C952:C1211)*SQRT(260) -> 0.019353687 | D952: =STDEV('Performance Lorde'!D952:D1211)*SQRT(260) -> 0.067554697 | E952: =STDEV('Performance Lorde'!E952:E1211)*SQRT(260) -> 0.1017269 | F952: =STDEV('Performance Lorde'!F952:F1211)*SQRT(260) -> 0.035414248 | G952: =IFERROR(STDEV('Performance Lorde'!G952:G1211)*SQRT(260),"-") -> 0.054702326
A953: 43756 | B953: =STDEV('Performance Lorde'!B953:B1212)*SQRT(260) -> 0.0041745082 | C953: =STDEV('Performance Lorde'!C953:C1212)*SQRT(260) -> 0.01934151 | D953: =STDEV('Performance Lorde'!D953:D1212)*SQRT(260) -> 0.067596996 | E953: =STDEV('Performance Lorde'!E953:E1212)*SQRT(260) -> 0.1018098 | F953: =STDEV('Performance Lorde'!F953:F1212)*SQRT(260) -> 0.035424833 | G953: =IFERROR(STDEV('Performance Lorde'!G953:G1212)*SQRT(260),"-") -> 0.054787065
A954: 43759 | B954: =STDEV('Performance Lorde'!B954:B1213)*SQRT(260) -> 0.004175425 | C954: =STDEV('Performance Lorde'!C954:C1213)*SQRT(260) -> 0.019357006 | D954: =STDEV('Performance Lorde'!D954:D1213)*SQRT(260) -> 0.067600197 | E954: =STDEV('Performance Lorde'!E954:E1213)*SQRT(260) -> 0.10180239 | F954: =STDEV('Performance Lorde'!F954:F1213)*SQRT(260) -> 0.035436601 | G954: =IFERROR(STDEV('Performance Lorde'!G954:G1213)*SQRT(260),"-") -> 0.054789716
A955: 43760 | B955: =STDEV('Performance Lorde'!B955:B1214)*SQRT(260) -> 0.0041716323 | C955: =STDEV('Performance Lorde'!C955:C1214)*SQRT(260) -> 0.019620768 | D955: =STDEV('Performance Lorde'!D955:D1214)*SQRT(260) -> 0.067226492 | E955: =STDEV('Performance Lorde'!E955:E1214)*SQRT(260) -> 0.10132612 | F955: =STDEV('Performance Lorde'!F955:F1214)*SQRT(260) -> 0.035290107 | G955: =IFERROR(STDEV('Performance Lorde'!G955:G1214)*SQRT(260),"-") -> 0.054703322
A956: 43761 | B956: =STDEV('Performance Lorde'!B956:B1215)*SQRT(260) -> 0.0041715476 | C956: =STDEV('Performance Lorde'!C956:C1215)*SQRT(260) -> 0.019616721 | D956: =STDEV('Performance Lorde'!D956:D1215)*SQRT(260) -> 0.067129412 | E956: =STDEV('Performance Lorde'!E956:E1215)*SQRT(260) -> 0.10117676 | F956: =STDEV('Performance Lorde'!F956:F1215)*SQRT(260) -> 0.035274704 | G956: =IFERROR(STDEV('Performance Lorde'!G956:G1215)*SQRT(260),"-") -> 0.054699986
A957: 43762 | B957: =STDEV('Performance Lorde'!B957:B1216)*SQRT(260) -> 0.0041760649 | C957: =STDEV('Performance Lorde'!C957:C1216)*SQRT(260) -> 0.019687361 | D957: =STDEV('Performance Lorde'!D957:D1216)*SQRT(260) -> 0.067192262 | E957: =STDEV('Performance Lorde'!E957:E1216)*SQRT(260) -> 0.10122614 | F957: =STDEV('Performance Lorde'!F957:F1216)*SQRT(260) -> 0.035337783 | G957: =IFERROR(STDEV('Performance Lorde'!G957:G1216)*SQRT(260),"-") -> 0.054687406
A958: 43763 | B958: =STDEV('Performance Lorde'!B958:B1217)*SQRT(260) -> 0.004172477 | C958: =STDEV('Performance Lorde'!C958:C1217)*SQRT(260) -> 0.019699522 | D958: =STDEV('Performance Lorde'!D958:D1217)*SQRT(260) -> 0.067154024 | E958: =STDEV('Performance Lorde'!E958:E1217)*SQRT(260) -> 0.10111097 | F958: =STDEV('Performance Lorde'!F958:F1217)*SQRT(260) -> 0.035353273 | G958: =IFERROR(STDEV('Performance Lorde'!G958:G1217)*SQRT(260),"-") -> 0.054549565
A959: 43766 | B959: =STDEV('Performance Lorde'!B959:B1218)*SQRT(260) -> 0.0041441867 | C959: =STDEV('Performance Lorde'!C959:C1218)*SQRT(260) -> 0.019680038 | D959: =STDEV('Performance Lorde'!D959:D1218)*SQRT(260) -> 0.067181564 | E959: =STDEV('Performance Lorde'!E959:E1218)*SQRT(260) -> 0.10115643 | F959: =STDEV('Performance Lorde'!F959:F1218)*SQRT(260) -> 0.035358748 | G959: =IFERROR(STDEV('Performance Lorde'!G959:G1218)*SQRT(260),"-") -> 0.054552686
A960: 43767 | B960: =STDEV('Performance Lorde'!B960:B1219)*SQRT(260) -> 0.0040937066 | C960: =STDEV('Performance Lorde'!C960:C1219)*SQRT(260) -> 0.019681332 | D960: =STDEV('Performance Lorde'!D960:D1219)*SQRT(260) -> 0.067030767 | E960: =STDEV('Performance Lorde'!E960:E1219)*SQRT(260) -> 0.1008986 | F960: =STDEV('Performance Lorde'!F960:F1219)*SQRT(260) -> 0.035332333 | G960: =IFERROR(STDEV('Performance Lorde'!G960:G1219)*SQRT(260),"-") -> 0.054419108
...

Sheet Foglio4
